#VRML_SIM R2022a utf8
WorldInfo {
}
Viewpoint {
  orientation -0.25207394002964084 -0.10361224564394243 0.9621451196729901 3.7831131326489706
  position 0.4755783545117846 0.36840350047737797 0.37861659184462815
  follow "minaros"
}
TexturedBackground {
  texture "empty_office"
}
TexturedBackgroundLight {
}
Robot {
  translation 0 -0.08 0
  children [
    HingeJoint {
      jointParameters HingeJointParameters {
        axis 0 1 0
        anchor 0 0 0.025
      }
      device [
        RotationalMotor {
          name "left wheel motor"
        }
      ]
      endPoint Solid {
        translation 0 0.045 0.025
        rotation 0 1 0 0
        children [
          DEF WHEEL Transform {
            rotation 1 0 0 1.5707996938995747
            children [
              Shape {
                appearance PBRAppearance {
                  baseColor 1 0 0
                  roughness 1
                  metalness 0
                }
                geometry Cylinder {
                  height 0.01
                  radius 0.025
                }
              }
            ]
          }
        ]
        name "left wheel"
        boundingObject USE WHEEL
        physics Physics {
        }
      }
    }
    HingeJoint {
      jointParameters HingeJointParameters {
        axis 0 1 0
        anchor 0 0 0.025
      }
      device [
        RotationalMotor {
          name "right wheel motor"
        }
      ]
      endPoint Solid {
        translation 0 -0.045 0.025
        rotation 0 1 0 0
        children [
          USE WHEEL
        ]
        name "right wheel"
        boundingObject USE WHEEL
        physics Physics {
        }
      }
    }
    Transform {
      translation 0 0 0.0415
      children [
        Shape {
          appearance PBRAppearance {
            baseColor 0 0 1
            roughness 1
            metalness 0
          }
          geometry DEF BODY Cylinder {
            height 0.08
            radius 0.045
          }
        }
      ]
    }
    DistanceSensor {
      translation 0.042 0.02 0.063
      rotation 0 0 1 0.5236003061004253
      children [
        DEF SENSOR Transform {
          rotation 0 1 0 1.5708
          children [
            Shape {
              appearance PBRAppearance {
                baseColor 1 1 0
                roughness 1
                metalness 0
              }
              geometry Cylinder {
                height 0.004
                radius 0.008
              }
            }
          ]
        }
      ]
      name "ds0"
      lookupTable [
        0 1020 0
        0.05 1020 0
        0.15 0 0
      ]
      numberOfRays 2
      aperture 1
    }
    DistanceSensor {
      translation 0.042 -0.02 0.063
      rotation 0 0 1 -0.5235996938995747
      children [
        USE SENSOR
      ]
      name "ds1"
      lookupTable [
        0 1020 0
        0.05 1020 0
        0.15 0 0
      ]
      numberOfRays 2
      aperture 1
    }
  ]
  name "my_robot"
  boundingObject Transform {
    translation 0 0 0.0415
    children [
      USE BODY
    ]
  }
  physics Physics {
  }
  controller ""
}
Ball {
  translation 0.37 0 0.28
}
E-puck {
  translation 0.23 0 0
  controller ""
}
RectangleArena {
  translation 0 0.1 0
  floorSize 1.5 2
  floorAppearance Parquetry {
    type "light strip"
  }
}
DEF top_cam Robot {
  translation 0 0 1.79
  rotation 0 0 1 1.5708
  children [
    Camera {
      rotation 0.5773489358556708 0.5773509358554485 -0.5773509358554485 2.0944
      children [
        DEF SHAPE_TOP_CAM Shape {
          appearance Appearance {
            material Material {
              emissiveColor 0 1 0
            }
          }
          geometry Box {
            size 0.01 0.01 0.01
          }
        }
      ]
      name "top camera robot"
      width 128
    }
  ]
  boundingObject USE SHAPE_TOP_CAM
  locked TRUE
}
Robot {
  translation 0.08 0.12 0.04
  rotation 0 1 0 0
  children [
    Lidar {
      translation 0.04 -0.005 0.02
      children [
        Solid {
          children [
            Shape {
              appearance Appearance {
                material Material {
                  emissiveColor 0.8 0 0
                }
              }
              geometry Box {
                size 0.002 0.002 0.002
              }
            }
          ]
        }
      ]
      numberOfLayers 1
    }
    Camera {
      translation 0.04 0.005 0.02
      children [
        Shape {
          appearance Appearance {
            material Material {
              emissiveColor 0.45098 0.823529 0.0862745
            }
          }
          geometry Box {
            size 0.002 0.002 0.002
          }
        }
      ]
    }
    HingeJoint {
      jointParameters HingeJointParameters {
      }
      device [
        RotationalMotor {
          name "right motor"
        }
      ]
      endPoint Solid {
        translation 0 -0.042 -4.04052e-07
        rotation 1 0 0 1.5708
        children [
          DEF wheel_shape Shape {
            geometry Cylinder {
              height 0.003
              radius 0.04
            }
          }
        ]
      }
    }
    HingeJoint {
      jointParameters HingeJointParameters {
      }
      device [
        RotationalMotor {
          name "left motor"
        }
      ]
      endPoint Solid {
        translation 0 0.042 -1.10196e-07
        rotation 1 0 0 1.5708
        children [
          USE wheel_shape
        ]
        name "solid(1)"
      }
    }
    Shape {
      appearance Appearance {
        material Material {
          emissiveColor 0.12549 0.290196 0.529412
        }
      }
      geometry Box {
        size 0.08 0.08 0.07
      }
    }
  ]
  name "minaros"
}
